Workbook

Sheet Transactions Raw
B2: # | C2: Date | D2: Direction | E2: Account | F2: Amount (ZAR) | G2: Notes
C3: 45717 | D3: Expense | E3: Public Liability Insurance | F3: 165.14
C4: 45717 | D4: Expense | E4: Phone | F4: 589
C5: 45717 | D5: Expense | E5: Internet | F5: 539
C6: 45717 | D6: Income | E6: Fees Earned | F6: 517 | G6: Olaotse
C7: 45719 | D7: Income | E7: Fees Earned | F7: 2140 | G7: Marli Kruger
C8: 45719 | D8: Income | E8: Fees Earned | F8: 1250 | G8: Elmien Pretorius
C9: 45719 | D9: Income | E9: Fees Earned | F9: 625 | G9: Lianelle Coetzee
C10: 45719 | D10: Income | E10: Fees Earned | F10: 1170 | G10: Isla Sampson
C11: 45720 | D11: Income | E11: Fees Earned | F11: 392 | G11: Sinawo
C12: 45720 | D12: Income | E12: Fees Earned | F12: 800 | G12: Amariah van Heerden
C13: 45720 | D13: Income | E13: Fees Earned | F13: 1250 | G13: Kenzi Beyers
C14: 45721 | D14: Expense | E14: Accounting Fees | F14: 780
C15: 45721 | D15: Expense | E15: Petrol | F15: 300
C16: 45721 | D16: Expense | E16: Entertainment | F16: 170
C17: 45721 | D17: Income | E17: Fees Earned | F17: 1550 | G17: Ntokozo Sello
C18: 45722 | D18: Expense | E18: Payment to contractor - Edmund | F18: 640
C19: 45722 | D19: Expense | E19: Payment to contractor - Edmund | F19: 1200
C20: 45724 | D20: Expense | E20: Petrol | F20: 1079.1
C21: 45724 | D21: Income | E21: Fees Earned | F21: 58 | G21: Khloe Clarvis
C22: 45724 | D22: Income | E22: Fees Earned | F22: 1550 | G22: Iyazile
C23: 45729 | D23: Expense | E23: Phone | F23: 89
C24: 45730 | D24: Income | E24: Fees Earned | F24: 1100 | G24: Zoe Sullivan
C25: 45733 | D25: Income | E25: Fees Earned | F25: 450 | G25: Mikayla Gomwe
C26: 45734 | D26: Expense | E26: Entertainment | F26: 4050 | G26: Joburg Theatre
C27: 45734 | D27: Income | E27: Fees Earned | F27: 1250 | G27: Eyana
C28: 45735 | D28: Expense | E28: Petrol | F28: 1045.95
C29: 45735 | D29: Expense | E29: Google Storage | F29: 184.99
C30: 45735 | D30: Expense | E30: Petrol | F30: 1045.95
C31: 45736 | D31: Expense | E31: Payment to contractor - Reese | F31: 875
C32: 45736 | D32: Expense | E32: Hall Hire Charterhouse | F32: 800
C33: 45736 | D33: Expense | E33: Payment to contractor - Luisa | F33: 2312.5
C34: 45736 | D34: Expense | E34: Hall Hire Church | F34: 5600
C35: 45736 | D35: Expense | E35: Storage for Costumes and Props | F35: 2250
C36: 45736 | D36: Expense | E36: Payment to contractor - Edmund | F36: 2000
C37: 45736 | D37: Expense | E37: Home Office Space Rent | F37: 3053
C38: 45736 | D38: Income | E38: Fees Earned | F38: 714 | G38: Theresho Mawela
C39: 45736 | D39: Income | E39: Fees Earned | F39: 1250 | G39: Aenea Cockrane
C40: 45736 | D40: Income | E40: Fees Earned | F40: 517 | G40: Sinawo
C41: 45736 | D41: Income | E41: Fees Earned | F41: 850 | G41: Nonyankezi
...

Sheet FY26 Trail Balance
I1: Start | J1: End
I2: 45717 | J2: 46082
B3: Jess Lombard Junior Dance Centre
B5: Trial Balance
B6: Year End | C6: 46081
B10: Account | C10: Amount (ZAR) | D10: Type
B11: Fees earned | C11: =SUMIFS('Transactions Raw'!$F$3:$F1367,'Transactions Raw'!$E$3:$E1367,'FY26 Trail Balance'!$B11,'Transactions Raw'!$C$3:$C1367,">="&$I$2,'Transactions Raw'!$C$3:$C1367,"<="&$J$2) | D11: I
B12: Ticket sales from Showcase | C12: 25251 | D12: I
B13: Accounting Fees | C13: =SUMIFS('Transactions Raw'!$F$3:$F1367,'Transactions Raw'!$E$3:$E1367,'FY26 Trail Balance'!$B13,'Transactions Raw'!$C$3:$C1367,">="&$I$2,'Transactions Raw'!$C$3:$C1367,"<="&$J$2) | D13: E
B14: Advertising | C14: =SUMIFS('Transactions Raw'!$F$3:$F1367,'Transactions Raw'!$E$3:$E1367,'FY26 Trail Balance'!$B14,'Transactions Raw'!$C$3:$C1367,">="&$I$2,'Transactions Raw'!$C$3:$C1367,"<="&$J$2) | D14: E
B15: Bank Charges | C15: =SUMIFS('Transactions Raw'!$F$3:$F1367,'Transactions Raw'!$E$3:$E1367,'FY26 Trail Balance'!$B15,'Transactions Raw'!$C$3:$C1367,">="&$I$2,'Transactions Raw'!$C$3:$C1367,"<="&$J$2) | D15: E
B16: Hall Hire Charterhouse | C16: =SUMIFS('Transactions Raw'!$F$3:$F1367,'Transactions Raw'!$E$3:$E1367,'FY26 Trail Balance'!$B16,'Transactions Raw'!$C$3:$C1367,">="&$I$2,'Transactions Raw'!$C$3:$C1367,"<="&$J$2) | D16: E
B17: Corporate Gifts | C17: =SUMIFS('Transactions Raw'!$F$3:$F1367,'Transactions Raw'!$E$3:$E1367,'FY26 Trail Balance'!$B17,'Transactions Raw'!$C$3:$C1367,">="&$I$2,'Transactions Raw'!$C$3:$C1367,"<="&$J$2) | D17: E
B18: Costumes and Props | C18: =SUMIFS('Transactions Raw'!$F$3:$F1367,'Transactions Raw'!$E$3:$E1367,'FY26 Trail Balance'!$B18,'Transactions Raw'!$C$3:$C1367,">="&$I$2,'Transactions Raw'!$C$3:$C1367,"<="&$J$2) | D18: E
B19: Theatre Hire | C19: =SUMIFS('Transactions Raw'!$F$3:$F1367,'Transactions Raw'!$E$3:$E1367,'FY26 Trail Balance'!$B19,'Transactions Raw'!$C$3:$C1367,">="&$I$2,'Transactions Raw'!$C$3:$C1367,"<="&$J$2) | D19: E
B20: Entertainment | C20: =SUMIFS('Transactions Raw'!$F$3:$F1367,'Transactions Raw'!$E$3:$E1367,'FY26 Trail Balance'!$B20,'Transactions Raw'!$C$3:$C1367,">="&$I$2,'Transactions Raw'!$C$3:$C1367,"<="&$J$2) | D20: E
B21: Roodepoort Dance Festival Entries | C21: =SUMIFS('Transactions Raw'!$F$3:$F1367,'Transactions Raw'!$E$3:$E1367,'FY26 Trail Balance'!$B21,'Transactions Raw'!$C$3:$C1367,">="&$I$2,'Transactions Raw'!$C$3:$C1367,"<="&$J$2) | D21: E
B22: Examination costs | C22: =SUMIFS('Transactions Raw'!$F$3:$F1367,'Transactions Raw'!$E$3:$E1367,'FY26 Trail Balance'!$B22,'Transactions Raw'!$C$3:$C1367,">="&$I$2,'Transactions Raw'!$C$3:$C1367,"<="&$J$2) | D22: E
B23: Hall Hire Church | C23: =SUMIFS('Transactions Raw'!$F$3:$F1367,'Transactions Raw'!$E$3:$E1367,'FY26 Trail Balance'!$B23,'Transactions Raw'!$C$3:$C1367,">="&$I$2,'Transactions Raw'!$C$3:$C1367,"<="&$J$2) | D23: E
B24: Flooring for Studio | C24: =SUMIFS('Transactions Raw'!$F$3:$F1367,'Transactions Raw'!$E$3:$E1367,'FY26 Trail Balance'!$B24,'Transactions Raw'!$C$3:$C1367,">="&$I$2,'Transactions Raw'!$C$3:$C1367,"<="&$J$2) | D24: E
B25: Internet | C25: =SUMIFS('Transactions Raw'!$F$3:$F1367,'Transactions Raw'!$E$3:$E1367,'FY26 Trail Balance'!$B25,'Transactions Raw'!$C$3:$C1367,">="&$I$2,'Transactions Raw'!$C$3:$C1367,"<="&$J$2) | D25: E
B26: Medals | C26: =SUMIFS('Transactions Raw'!$F$3:$F1367,'Transactions Raw'!$E$3:$E1367,'FY26 Trail Balance'!$B26,'Transactions Raw'!$C$3:$C1367,">="&$I$2,'Transactions Raw'!$C$3:$C1367,"<="&$J$2) | D26: E
B27: Motor Vehicle Expense | C27: =SUMIFS('Transactions Raw'!$F$3:$F1367,'Transactions Raw'!$E$3:$E1367,'FY26 Trail Balance'!$B27,'Transactions Raw'!$C$3:$C1367,">="&$I$2,'Transactions Raw'!$C$3:$C1367,"<="&$J$2) | D27: E
B28: Payment to contractor - Edmund | C28: =SUMIFS('Transactions Raw'!$F$3:$F1367,'Transactions Raw'!$E$3:$E1367,'FY26 Trail Balance'!$B28,'Transactions Raw'!$C$3:$C1367,">="&$I$2,'Transactions Raw'!$C$3:$C1367,"<="&$J$2) | D28: E
B29: Payment to contractor - Backstage Help at Showcase | C29: =SUMIFS('Transactions Raw'!$F$3:$F1367,'Transactions Raw'!$E$3:$E1367,'FY26 Trail Balance'!$B29,'Transactions Raw'!$C$3:$C1367,">="&$I$2,'Transactions Raw'!$C$3:$C1367,"<="&$J$2) | D29: E
B30: Payment to contractor - Videographer for Showcase | C30: =SUMIFS('Transactions Raw'!$F$3:$F1367,'Transactions Raw'!$E$3:$E1367,'FY26 Trail Balance'!$B30,'Transactions Raw'!$C$3:$C1367,">="&$I$2,'Transactions Raw'!$C$3:$C1367,"<="&$J$2) | D30: E
B31: Payment to contractor - Reese | C31: =SUMIFS('Transactions Raw'!$F$3:$F1367,'Transactions Raw'!$E$3:$E1367,'FY26 Trail Balance'!$B31,'Transactions Raw'!$C$3:$C1367,">="&$I$2,'Transactions Raw'!$C$3:$C1367,"<="&$J$2) | D31: E
B32: Payment to contractor - Jenna (Exam Music) | C32: =SUMIFS('Transactions Raw'!$F$3:$F1367,'Transactions Raw'!$E$3:$E1367,'FY26 Trail Balance'!$B32,'Transactions Raw'!$C$3:$C1367,">="&$I$2,'Transactions Raw'!$C$3:$C1367,"<="&$J$2) | D32: E
B33: Payment to contractor - Luisa | C33: =SUMIFS('Transactions Raw'!$F$3:$F1367,'Transactions Raw'!$E$3:$E1367,'FY26 Trail Balance'!$B33,'Transactions Raw'!$C$3:$C1367,">="&$I$2,'Transactions Raw'!$C$3:$C1367,"<="&$J$2) | D33: E
B34: Payment to contractor - Cristina | C34: =SUMIFS('Transactions Raw'!$F$3:$F1367,'Transactions Raw'!$E$3:$E1367,'FY26 Trail Balance'!$B34,'Transactions Raw'!$C$3:$C1367,">="&$I$2,'Transactions Raw'!$C$3:$C1367,"<="&$J$2) | D34: E
B35: Petrol | C35: =SUMIFS('Transactions Raw'!$F$3:$F1367,'Transactions Raw'!$E$3:$E1367,'FY26 Trail Balance'!$B35,'Transactions Raw'!$C$3:$C1367,">="&$I$2,'Transactions Raw'!$C$3:$C1367,"<="&$J$2) | D35: E
B36: Phone | C36: =SUMIFS('Transactions Raw'!$F$3:$F1367,'Transactions Raw'!$E$3:$E1367,'FY26 Trail Balance'!$B36,'Transactions Raw'!$C$3:$C1367,">="&$I$2,'Transactions Raw'!$C$3:$C1367,"<="&$J$2) | D36: E
B37: Printing | C37: =SUMIFS('Transactions Raw'!$F$3:$F1367,'Transactions Raw'!$E$3:$E1367,'FY26 Trail Balance'!$B37,'Transactions Raw'!$C$3:$C1367,">="&$I$2,'Transactions Raw'!$C$3:$C1367,"<="&$J$2) | D37: E
B38: Public Liability Insurance | C38: =SUMIFS('Transactions Raw'!$F$3:$F1367,'Transactions Raw'!$E$3:$E1367,'FY26 Trail Balance'!$B38,'Transactions Raw'!$C$3:$C1367,">="&$I$2,'Transactions Raw'!$C$3:$C1367,"<="&$J$2) | D38: E
B39: RAD/AIDT Membership Fee | C39: =SUMIFS('Transactions Raw'!$F$3:$F1367,'Transactions Raw'!$E$3:$E1367,'FY26 Trail Balance'!$B39,'Transactions Raw'!$C$3:$C1367,">="&$I$2,'Transactions Raw'!$C$3:$C1367,"<="&$J$2) | D39: E
B40: CPD Courses | C40: =SUMIFS('Transactions Raw'!$F$3:$F1367,'Transactions Raw'!$E$3:$E1367,'FY26 Trail Balance'!$B40,'Transactions Raw'!$C$3:$C1367,">="&$I$2,'Transactions Raw'!$C$3:$C1367,"<="&$J$2) | D40: E
B41: Sewing | C41: =SUMIFS('Transactions Raw'!$F$3:$F1367,'Transactions Raw'!$E$3:$E1367,'FY26 Trail Balance'!$B41,'Transactions Raw'!$C$3:$C1367,">="&$I$2,'Transactions Raw'!$C$3:$C1367,"<="&$J$2) | D41: E
B42: Stationery | C42: =SUMIFS('Transactions Raw'!$F$3:$F1367,'Transactions Raw'!$E$3:$E1367,'FY26 Trail Balance'!$B42,'Transactions Raw'!$C$3:$C1367,">="&$I$2,'Transactions Raw'!$C$3:$C1367,"<="&$J$2) | D42: E
B43: Storage for Costumes and Props | C43: =SUMIFS('Transactions Raw'!$F$3:$F1367,'Transactions Raw'!$E$3:$E1367,'FY26 Trail Balance'!$B43,'Transactions Raw'!$C$3:$C1367,">="&$I$2,'Transactions Raw'!$C$3:$C1367,"<="&$J$2) | D43: E
B44: Studio supplies - Apple Music | C44: =SUMIFS('Transactions Raw'!$F$3:$F1367,'Transactions Raw'!$E$3:$E1367,'FY26 Trail Balance'!$B44,'Transactions Raw'!$C$3:$C1367,">="&$I$2,'Transactions Raw'!$C$3:$C1367,"<="&$J$2) | D44: E
...

Sheet Sheet2
B2: Cash and cash equivalents | D2: A
B3: Trade payables | C3: =SUMIFS('Transactions Raw'!$F$3:$F1367,'Transactions Raw'!$E$3:$E1367,Sheet2!$B3,'Transactions Raw'!$C$3:$C1367,">="&'FY26 Trail Balance'!$I$2,'Transactions Raw'!$C$3:$C1367,"<="&'FY26 Trail Balance'!$J$2) | D3: L
B4: Trade receivables | D4: A
F13: 44988 | G13: Income | H13: Fees earned | I13: 595 | J13: Felicity Hemphill - RAD Exam Fees (Not to me)
F14: 44991 | G14: Income | H14: Fees earned | I14: 840 | J14: Kate Lass - RAD Exam Fees (Not to me)
F15: 44991 | G15: Income | H15: Fees earned | I15: 595 | J15: Alexis Davies - RAD Exam Fees (Not to me)
F16: 44992 | G16: Income | H16: Fees earned | I16: 680 | J16: Danyelle Minnaar - RAD Exam Fees (Not to me)
F17: 44993 | G17: Income | H17: Fees earned | I17: 595 | J17: Abigail Jordaan - RAD Exam Fees (Not to me)
F18: 44993 | G18: Income | H18: Fees earned | I18: 720 | J18: Abigail Oliver - RAD Exam Fees (Not to me)
F19: 45005 | G19: Income | H19: Fees earned | I19: 500 | J19: Peyton Wolfaardt - RAD Exam Fees (Not to me)
F20: 45005 | G20: Income | H20: Fees earned | I20: 720 | J20: Leanay Opperman - RAD Exam Fees (Not to me)
F21: 45007 | G21: Income | H21: Fees earned | I21: 595 | J21: Mia-Mari van Rooyen - RAD Exam Fees (Not to me)
F22: 45007 | G22: Income | H22: Fees earned | I22: 840 | J22: Warona Moatlhodi - RAD Exam Fees (Not to me)
F23: 45008 | G23: Income | H23: Fees earned | I23: 680 | J23: Leandra Harris - RAD Exam Fees (Not to me)
F24: 45008 | G24: Income | H24: Fees earned | I24: 500 | J24: Zoey van Gils - RAD Exam Fees (Not to me)
... F62: 45030 | G62: Income | H62: Fees earned | I62: 600 | J62: Chelsea Kgopana - RAD Exam Fees (Not to me)
